Workbook

Sheet Table 2
A2: Travel Itinerary
A3: Quote No. : ES 102 | B3: Client Name: Contact Number: | E3: Travel Date : 25 Oct 2025
A4: Arrival Date : 25 Oct 2025 | B4: Guest Name : -- Guest Number : -- | E4: Total Person = 4 Adults | F4: 6
A5: Departure Date : 4 July 2025 | E5: 3 Nights / 4 Days
A6: PLACE | B6: HOTEL NAME ( With Breakfast ) | E6: PERIOD OF STAY | I6: Adult | K6: EA | M6: CNB
A7: Singapore | B7: Hotel Boss | E7: 4 / Nights | F7: 3 | G7: =VLOOKUP(B7,Sheet2!A:B,2,FALSE) -> 104 | H7: =G7*F7 -> 312 | I7: =H7/2 -> 156 | J7: =VLOOKUP(B7,Sheet2!A:C,3,FALSE) -> 0
F8: 4 | G8: =VLOOKUP(B8,Sheet2!A:B,2,FALSE) -> #N/A | H8: =G8*F8 -> #N/A | I8: =H8/2 -> #N/A | J8: =VLOOKUP(B8,Sheet2!A:C,3,FALSE) -> #N/A | K8: =(J8*F8) -> #N/A | L8: =VLOOKUP(B8,Sheet2!A:D,4,FALSE) -> #N/A | M8: =(L8*F8) -> #N/A
A9: Day -Date ( Approx ) | B9: Pick-Up Time | C9: Pick-Up Point | D9: Tour/Tranasfer program | F9: Meal | I9: =SUM(I8:I8) -> #N/A | K9: =SUM(K8:K8) -> #N/A | M9: =SUM(M8:M8) -> #N/A
A10: 45944 | B10: TBA | C10: Singapore Airport | D10: Pick up From Airport - Hotel Drop - Pick up From Hotel 5:00 PM - Singapore Panaromic Drive2.5 hrs with Merlion park, & Chinese Temple stop for Pics. Chinatown, Padang Area drive through only.with Singapore Flyre - Hotel Drop | F10: N/A | G10: =VLOOKUP(D10,Sheet1!A:B,2,FALSE) -> #N/A | H10: =VLOOKUP(D10,Sheet1!A:C,3,FALSE) -> #N/A | I10: =VLOOKUP(D10,Sheet1!A:D,4,FALSE) -> #N/A | J10: =VLOOKUP(F10,Sheet1!G:H,2,FALSE) -> 0
A11: 45945 | B11: TBA | C11: Hotel | D11: Pick up From Hotel 3:00 PM - Gardens By The Bay (Super Tree + Cloud Forest) + Sky Park @ Marina Bay Sands Sky Park - Hotel Drop 8:00PM | F11: N/A | G11: =VLOOKUP(D11,Sheet1!A:B,2,FALSE) -> #N/A | H11: =VLOOKUP(D11,Sheet1!A:C,3,FALSE) -> #N/A | I11: =VLOOKUP(D11,Sheet1!A:D,4,FALSE) -> #N/A | J11: =VLOOKUP(F11,Sheet1!G:H,2,FALSE) -> 0
A12: 45946 | B12: TBA | C12: Hotel | D12: Pick up From Hotel 9:00 AM - Full Day Universal studio - Hotel Drop 7:00PM | F12: N/A | G12: =VLOOKUP(D12,Sheet1!A:B,2,FALSE) -> #N/A | H12: =VLOOKUP(D12,Sheet1!A:C,3,FALSE) -> #N/A | I12: =VLOOKUP(D12,Sheet1!A:D,4,FALSE) -> #N/A | J12: =VLOOKUP(F12,Sheet1!G:H,2,FALSE) -> 0
A13: 45947 | B13: TBA | C13: Hotel | D13: Pick up from Hotel 9:00 AM - Full day Sentosa Island Tour (1Way Cable Car +Madame Tussauds 5 In 1 (Madame Tussauds + Images of Singapore + Boat Ride + 4D Marvel + Ultimate Film Star)+ Wings Of Time) - Hotel Drop 8:30PM | F13: N/A | G13: =VLOOKUP(D13,Sheet1!A:B,2,FALSE) -> #N/A | H13: =VLOOKUP(D13,Sheet1!A:C,3,FALSE) -> #N/A | I13: =VLOOKUP(D13,Sheet1!A:D,4,FALSE) -> #N/A | J13: =VLOOKUP(F13,Sheet1!G:H,2,FALSE) -> 0
D14: ------ | F14: N/A | G14: =VLOOKUP(D14,Sheet1!A:B,2,FALSE) -> 0 | H14: =VLOOKUP(D14,Sheet1!A:C,3,FALSE) -> 0 | I14: =VLOOKUP(D14,Sheet1!A:D,4,FALSE) -> 0 | J14: =VLOOKUP(F14,Sheet1!G:H,2,FALSE) -> 0
A15: 45949 | B15: TBA | C15: Hotel | D15: ------ | F15: N/A | G15: =VLOOKUP(D15,Sheet1!A:B,2,FALSE) -> 0 | H15: =VLOOKUP(D15,Sheet1!A:C,3,FALSE) -> 0 | I15: =VLOOKUP(D15,Sheet1!A:D,4,FALSE) -> 0 | J15: =VLOOKUP(F15,Sheet1!G:H,2,FALSE) -> 0
D16: ------ | F16: N/A | G16: =VLOOKUP(D16,Sheet1!A:B,2,FALSE) -> 0 | H16: =VLOOKUP(D16,Sheet1!A:C,3,FALSE) -> 0 | I16: =VLOOKUP(D16,Sheet1!A:D,4,FALSE) -> 0 | J16: =VLOOKUP(F16,Sheet1!G:H,2,FALSE) -> 0
D17: ------ | F17: N/A | G17: =VLOOKUP(D17,Sheet1!A:B,2,FALSE) -> 0 | H17: =VLOOKUP(D17,Sheet1!A:C,3,FALSE) -> 0 | I17: =VLOOKUP(D17,Sheet1!A:D,4,FALSE) -> 0 | J17: =VLOOKUP(F17,Sheet1!G:H,2,FALSE) -> 0
A18: Note : Any Airport pickup waiting time 1 Hour from the time of landing of flight. And pickup time from hotel for any international flight 4 hour before departure time, If Any Flight Delay / Early inform us in advance.If any flight early/delay/cancelled due to any reason are not responsible for pickup/drop or missed flight due to pickup/drop. Extra charges applicable in pickup/drop to/from airport without prior information of above. | G18: Adult | H18: Child | I18: Transfer | J18: Meal
A19: Breakfast At Hotel. | G19: =SUM(G10:G17) -> #N/A | H19: =SUM(H10:H17) -> #N/A | I19: =SUM(I10:I17) -> #N/A | J19: =SUM(J10:J17) -> 0
A20: Remark 1 : Buy local Sim card at Arrival Airport and send us guest number on our whatsup number for communication. In any airport pickup /drop 1 bag of 15Kg luggage bag per person and 1 hand bag 7 kg per person allowed in car, if more bags extra charges pay by guest. | I20: =I19/F4 -> #N/A
A21: Adult Price : 949 SGD PP ( Hotel + Food + Transport + Activity Sightseen ) | G21: Adult Price PP | H21: EA Price PP | I21: CWB PRICE PP
G22: =SUM(G19,J19,I20,) -> #N/A | H22: =SUM(G19,H20,I19,K9,,) -> #N/A | I22: =SUM(H19,I20,J19,) -> #N/A
A23: SINGAPORE TERMS AND CONDITIONS
A24: Remark:
A25: This is a quotation only; no hotel bookings have been made.
A26: Reservations will be processed only upon receiving confirmation.
A27: Rates and room availability are subject to change and will be reconfirmed at the time of booking.
A28: The quoted rates are valid only if the number of participants remains unchanged.
A29: Prices are subject to change without prior notice and do not apply during peak surcharge periods.
A30: Bedding configuration (Double/Twin) is at the discretion of the hotel and will be confirmed upon check-in, subject to availability.
A33: Price IncludeS:
A34: Additional Charges & Conditions:
A35: Bank Remittance Charges: SGD 30.00 per transaction (Not applicable for INR payments to an Indian account)
A36: Midnight Surcharge: SGD 10.00 per person per way (Applicable for transfers between 2200 hrs – 0700 hrs)
... A150: Detail Itinerary
A151: Day 01 | B151: =VLOOKUP(D10,Sheet3!A:B,2,FALSE) -> #N/A
A152: Day 02 | B152: =VLOOKUP(D11,Sheet3!A:B,2,FALSE) -> #N/A
A153: Day 03 | B153: =VLOOKUP(D12,Sheet3!A:B,2,FALSE) -> • Today after your breakfast our tour guide will pick up you by 9:00AM • Full day visit to Universal Studios Singapore Including: - Hollywood Zone, - New York Zone, - Battle star Galactica, - Transformers, - Revenge Of the Mummy, - The lost World, - Shark 4-D Adventure, - Madagascar After your amazing experience of Universal studios you will be dropped off to your hotel by 6:00PM. Then you can relax at your hotel or Rome around your hotel.
A154: Day 04 | B154: =VLOOKUP(D13,Sheet3!A:B,2,FALSE) -> #N/A
A155: Day 05 | B155: =VLOOKUP(D14,Sheet3!A:B,2,FALSE) -> 0
A156: Day 06 | B156: =VLOOKUP(D15,Sheet3!A:B,2,FALSE) -> 0
...

Sheet Sheet1
A1: Arrival at Singapore Airport - Transfer to Hotel. | D1: 35 | G1: Dinner | H1: 17
A2: Pick up from Singapore Hotel - Singapore Airport Drop | D2: 35 | G2: Lunch | H2: 17
A3: Pick up From Ferry / Cruise Terminal - Hotel Drop | D3: 35 | G3: Dinner & Lunch | H3: 34
A4: Pick up From Singapore Hotel / Drop at Ferry / Cruise Terminal | D4: 35 | G4: N/A | H4: 0
A5: Pick up From Bus Terminal - Hotel Drop | D5: 35
A6: Pick up From Singapore Hotel - Bus Terminal Drop | D6: 35
A7: Pick up From Singapore Airport - Cruise Terminal Drop | D7: 35
A8: Pick up From Cruise Terminal -Singapore Airport Drop | D8: 35
A9: ------ | B9: 0 | C9: 0 | D9: 0
A10: ------ | B10: 0 | C10: 0 | D10: 0
A11: Pick up From Singapore Airport - Hotel Drop - Pick up From Hotel 5:00 PM - Singapore Panaromic Drive2.5 hrs with Merlion park, & Chinese Temple stop for Pics. Chinatown, Padang Area drive through only.with Singapore Flyre - Hotel Drop | B11: 38 | C11: 25 | D11: 150
A12: Pick up From Singapore Airport - Hotel Drop - Pick up from hotel 5:00 PM - Singapore City Tour (2.5 hrs with Merlion park, Flyer & Chinese Temple stop for Pics. Chinatown, Padang Area drive through only.- Hotel Drop 8:00PM | D12: 115
A13: Pick up From Singapore Airport - Hotel Drop - Pick up from hotel 5:00 PM - Marina Bay Sends Sky Park + Gardens By The Bay - Hotel Drop 9:00PM | B13: 68 | C13: 55 | D13: 105
A14: Pick up From Singapore hotel 12:00 AM - Singapore City Tour 2.5 hrs with Merlion park, Flyer & Chinese Temple stop for Pics. Chinatown, Padang Area drive through only.- Hotel Drop 3:00PM | D14: 80
A15: Pick up From hotel 9:00 AM - Singapore City Tour 2.5 hrs with Merlion park, Flyer & Chinese Temple stop for Pics. Chinatown, Padang Area drive through only.-Air port Drop | D15: 115
A16: Pick up From Singapore Airport - Hotel Drop - Hotel Pick up 5:00 PM - Marina Bay Sands Sky Park Observation Deck - Hotel Drop 8:00PM | B16: 40 | C16: 35 | D16: 105
A17: Pick up From Singapore Airport - Hotel Drop - Hotel Pick up 5:00 PM - Bird Paradise - Hotel Drop 8:00PM | B17: 43 | C17: 33 | D17: 105
A18: Pick up From Singapore Airport - Hotel Drop - Hotel Pick up 5:30 PM- Night Safari Tour (with complimentary Tram Ride And Animal show) - Hotel Drop 9:30PM | B18: 44 | C18: 37 | D18: 105
A19: Pick up From Singapore Hotel 5:00 PM- Night Safari Tour (with complimentary Tram Ride And Animal show) - Hotel Drop 9:00PM | B19: 44 | C19: 37 | D19: 70
A20: Pick up From Singapore Hotel 9:00 AM - Full Day Sentosa Island Tour (1 Way Cable Car + Madame Tussauds + Wings Of Time) - Hotel Drop 8:30PM | B20: 60 | C20: 55 | D20: 70
A21: Pick up from Singapore Hotel 9:00 AM - Singapore City Tour 2.5 hrs with Merlion park, Flyer & Chinese Temple stop for Pics. Chinatown, Padang Area drive through only+ Sentosa Island Tour (1Way Cable Car +Madame Tussauds 4 In 1 (Madame Tussauds + Images of Singapore + 4D Marvel + Ultimate Film Star)+ Wings Of Time) - Hotel Drop 8:30PM | B21: 60 | C21: 60 | D21: 150
A22: Pick up from Singapore Hotel 9:00 AM - Full day Sentosa Island Tour (1Way Cable Car +Madame Tussauds 4 In 1 (Madame Tussauds + Images of Singapore + 4D Marvel + Ultimate Film Star)+ Wings Of Time) - Hotel Drop 8:30PM | B22: 60 | C22: 60 | D22: 70
A23: Pick up from Singapore Hotel 9:00 AM - Full day Sentosa Island Tour (1Way Cable Car +Madame Tussauds 5 In 1 (Madame Tussauds + Images of Singapore + Boat Ride + 4D Marvel + Ultimate Film Star)+ Wings Of Time) - Hotel Drop 8:30PM | B23: 63 | C23: 59 | D23: 70
A24: Pick up from Singapore Hotel 9:00 AM - Full day Sentosa Island Tour (2Way Cable Car + Siloso Beach + Wings Of Time) - Hotel Drop 8:30PM | B24: 36 | C24: 31 | D24: 70
A25: Pick up From Singapore Hotel 9:00 AM - Full Day Sentosa Island Tour ( 1 Way Cable Car + Luge and Sky Ride + Wings Of Time) - Hotel Drop 8:30PM | B25: 75 | C25: 70 | D25: 70
A26: Pick up From Singapore Hotel 10:00 PM - Half day City Tour2.5 hrs withMerlion park, Flyer & Chinese Temple stop for Pics. Chinatown, Padang Area drive through only. + Sentosa Island Tour (1Way Cable Car +Madame Tussauds 5 In 1 (Madame Tussauds + Images of Singapore + Boat Ride + 4D Marvel + Ultimate Film Star) - Hotel Drop 9:15PM | B26: 63 | C26: 59 | D26: 115
A27: Pick up From Singapore Hotel 10:00 PM - Half day City Tour With Merlion park, Flyer & Chinese Temple stop for Pics.Chinatown, Padang Area drive through only. + Sentosa Island With Cable car and Wings of Time - Hotel Drop 9:15PM | B27: 36 | C27: 31 | D27: 115
... A52: Pick up From Singapore Hotel 9:00 AM - Gardens by the bay (cloud forest +Flower dome with Jurassic world) +MBS sky park (dated & non-peak-till 4pm only-subject to availability) -Hotel Drop 4:00PM | B52: 64 | C52: 59 | D52: 70
A53: Free Day For Shopping and Relaxing
A54: Pick up From Singapore Hotel - Garden by the bay (cloud forest +Flower dome with Jurassic world) +MBS sky park (dated & non-peak-till 4pm only-subject to availability) + Art and science museum + Hotel Drop | B54: 92 | C54: 78 | D54: 105
A60: Pick up From Genting Hotel - Drop at Airport
A61: Pick up From Genting Hotel - Drop at Coach Station
A62: Pick up from KL Hotel - Drop at Coach Station
A63: Pick up From KL Hotel - Putrajaya Tour - KL Hotel Drop
A64: Pick up From KLIA - Enroute Putrajaya Tour - KL Hotel Drop
A65: Pick up From KLIA - Hotel Drop
A66: Pick up From KLIA - 4 Hrs City Tour With KL Tower Photo Stop - Hotel Drop
A67: Pick up From KL coach station - Hotel Drop
A68: Pick up From KL coach station - Genting Hotel Drop
A69: Pick up From KL Hotel - 10 Hrs Tour ( 4 Hrs City Tour With KL Tower Photo Stop + Batu cave 1 Hrs + Genting 5 Hrs Tour ) - KL Hotel Drop
...

Sheet Sheet2
A1: HOTEL NAME | B1: ADULT RATE | C1: EXTRA ADULT | D1: CHILD NO BED
A3: SINGAPORE HOTELS
A4: Value Hotel Thomson
A5: 3 STAR
A6: V Hotel Lavender | B6: 180
A7: V Hotel Bencoolen
A8: Aqueen Prestige Hotel Jalan Besar
A9: Aqueen Prestige Hotel Lavender
A10: Hotel Chancellor | B10: 180
A11: Ibis Styles Singapore Albert | B11: 91 | D11: 19
A12: Ibis Budget Selegie | B12: 77
A13: Ibis Budget Imperial | B13: 150
A14: Ibis Novena | B14: 94
A15: Ibis Bencoolen | B15: 230
A17: 4 STAR
A18: Village Hotel Bugis
A19: Village Hotel Albert Court
A20: Mercure Singapore Tyrwhitt | B20: 99
A21: PARKROYAL on Beach Road
A22: Novotel Singapore On Kitchener | B22: 140
A23: Furama Riverfront
A24: Furama City Center
A25: Hotel MI Bencoolen
A26: Copthorn Kings
A27: Oasia Hotel Novena
A28: Hotel Traveltine
A29: Hotel Boss | B29: 104
A31: 5 STAR
A32: Goodwood Park Hotel
A33: Grand Copthorne Waterfront
A34: Orchard Hotel
A35: One Farrer Hotel | B35: 285
A36: Concorde Hotel
A37: Pan Pacific Singapore
A38: Pan Pacific Orchard
A39: Parkroyal Collection Marina Bay

Sheet Sheet3
A1: Arrival at Singapore Airport - Transfer to Hotel. | B1: ● ARRIVAL SINGAPORE AIRPORT - Arrive In Jewel Changi International Airport. - Our Private Car Will Pick You Up From The Airport And Head Towards The Hotel. - Early Check-in is not included . Take Necessary Rest After Flight.
A2: Pick up from Hotel - Singapore Airport Drop | B2: ♦Time to say Good Bye to a Beautiful Singapore City. ♦With lots of Good Memories and Photos. ♦Our Private Car Will Drop you to The Airport for Your Departure.
A3: Pick up From Ferry / Cruise Terminal - Hotel Drop | B3: ●Arriving by ferry or cruise? Skip the hassle and start your stay smoothly with our prompt pickup service from the terminal, delivering you comfortably and directly to your hotel. Relax—we’ve got your arrival covered.
A4: Pick up From Hotel / Drop at Ferry / Cruise Terminal | B4: ●Let's Pack your bags "Enjoy a hassle-free start to your journey with our convenient hotel pickup and smooth drop-off at the ferry / Cruise terminal—comfort, punctuality, and peace of mind, all in one ride."
A5: Pick up From Bus Terminal - Hotel Drop | B5: ●Arriving at the bus terminal? Let us take care of the next step. Our friendly and efficient transfer service picks you up right on arrival and takes you directly to your hotel—comfortably, safely, and without the stress.
A6: Pick up From Hotel - Bus Terminal Drop | B6: ●Wrap up your stay without the stress. Our professional transfer service picks you up from your hotel and drops you off at the bus terminal comfortably and on time, ensuring a smooth and worry-free departure.
A7: Pick up From Airport - Cruise Terminal Drop | B7: ●Touch down and set sail with ease. Our professional airport pickup service ensures a smooth transition from your flight to the cruise terminal. With timely pickups, comfortable vehicles, and friendly assistance, you can skip the stress and start your cruise adventure relaxed and ready.
A8: Pick up From Cruise Terminal - Airport Drop | B8: ●End your cruise as smoothly as it began with our reliable transfer service. We’ll pick you up directly from the cruise terminal and ensure a comfortable, on-time ride to the airport—so you can travel home relaxed and worry-free."
A9: ------
A10: ------
A11: Pick up From Airport - Hotel Drop - Pick up from hotel 5:00 PM - Half Day City Tour - Hotel Drop 8:00PM | B11: ● ARRIVAL SINGAPORE AIRPORT Arrive In Jewel Changi International Airport. - Our Private Car Will Pick You Up From The Airport And Head Towards The Hotel. - Early Check-in is not included . Take Necessary Rest After Flight. • After taking some rest by 5:00PM our Car will take you for Singapore City tour at there you can see: - Merlion Park - Chinatown - Little India - Orchard Road Then You will be dropped off to your hotel by 8:00PM
A12: Pick up From Airport - Hotel Drop - Pick up from hotel 5:00 PM - Gardens By The Bay + Marina Bay Sends Sky Park - Hotel Drop 9:00PM | B12: ● ARRIVAL SINGAPORE AIRPORT Arrive In Jewel Changi International Airport. - Our Private Car Will Pick You Up From The Airport And Head Towards The Hotel. - Early Check-in is not included . Take Necessary Rest After Flight. Then you are going to Visit Marina bay Sands Park here you can explore: - Here you can Roam in the luxurious Mall - You Can do Shopping from top brands outlets - Enjoy your lunchtime by your own - You can go on the top of the deck and enjoy 360 degree panoramic view - Take some photos
A13: Pick up From hotel 12:00 AM - Half Day Singapore City Tour - Hotel Drop 3:00PM | B13: • After taking Your Breakfast our Car will take you for Singapore City tour at there you can see: - Merlion Park - Chinatown - Little India - Lunch at a hawker center by your own - Orchard Road Then You will be dropped off to your hotel by 3:00PM
A14: Pick up From Airport - Hotel Drop - Hotel Pick up 5:00 PM - Marina Bay Sands Sky Park Observation Deck - Hotel Drop 8:00PM | B14: ● ARRIVAL SINGAPORE AIRPORT - Arrive In Jewel Changi International Airport. - Our Private Car Will Pick You Up From The Airport And Head Towards The Hotel. - Early Check-in is not included . Take Necessary Rest After Flight. Then our Car will pickup you from Hotel By 5:00PM to Marina Bay Sands Sky Park here you can Enjoy - Here you can Roam in the luxurious Mall - You Can do Shopping from top brands outlets - Enjoy your lunchtime by your own - You can go on the top of the deck and enjoy 360 degree panoramic view - Take some photos Then You will be dropped off to your hotel by 8:00PM
A15: Pick up From Airport - Hotel Drop - Hotel Pick up 5:00 PM - Bird Paradise - Hotel Drop 8:00PM | B15: ● ARRIVAL SINGAPORE AIRPORT ♦ Arrive In Jewel Changi International Airport. ♦ Our Private Car Will Pick You Up From The Airport And Head Towards The Hotel. ♦ Early Check-in is not included . Take Necessary Rest After Flight. • After that by 5:00PM you will be taken to Bird Paradise here you can explore: - Penguin cove - Crimson Wetlands - Heart of Africa - Winged Sanctuary • You can also Enjoy Shows: - Predators on Wings - Wings of the World After enjoying in Birdparadise you will be dropped off to your hotel by 8:00PM
A16: Pick up From Airport - Hotel Drop - Hotel Pick up 5:00 PM- Night Safari Tour - Hotel Drop 9:00PM | B16: ● ARRIVAL SINGAPORE AIRPORT ♦ Arrive In Jewel Changi International Airport. ♦ Our Private Car Will Pick You Up From The Airport And Head Towards The Hotel. ♦ Early Check-in is not included . Take Necessary Rest After Flight. • Then you are taken to the Night Safari by 5:00PM here you can enjoy: - Tram ride - Walking Trails - Creature of the Night Show - Keeper talks and Feeding Sessions - Animals you can explore there: Big cats, Asian wild Dogs, Tapirs, Red dears, African Lion, Indian Gaur, Cape buffalo, Malayan Tiger, Asian Elephant, Giant Monitor Lizard, Fishing Cat Etc... • And then go back to your Hotel by 9:00PM. Take your Dinner by your own and relax.
A17: Pick up From Hotel 5:00 PM- Night Safari Tour - Hotel Drop 9:00PM | B17: • After Taking your Breakfast enjoy at your Hotel Pool side then by 5:00PM Let’s Start your exploration with Night Safari here you can explore: - Tram ride - Walking Trails - Creature of the Night Show - Keeper talks and Feeding Sessions - Animals you can explore there: Big cats, Asian wild Dogs, Tapirs, Red dears, African Lion, Indian Gaur, Cape buffalo, Malayan Tiger, Asian Elephant, Giant Monitor Lizard, Fishing Cat Etc... • And then go back to your Hotel by 9:00PM. Take your Dinner by your own and relax.
A18: Pick up From Hotel 9:00 AM - Full Day Sentosa Island Tour (1 Way Cable Car + Madame Tussauds + Wings Of Time) - Hotel Drop 8:30PM | B18: Today you are going to explore Sentosa Island by 9:00AM - Kick off your Sentosa adventure with a 1-way Cable Car ride, soaking in stunning views of the city and coastline. - Explore Madame Tussauds Singapore, where you’ll meet lifelike wax figures, enjoy immersive exhibits, and step into the spotlight with Marvel 4D and more. - End your day with the spectacular Wings of Time – a dazzling night show of lights, water, and fireworks set against the open sea. - A perfect blend of fun, fame, and unforgettable memories! Then you will be dropped off to your Hotel by 8:30PM
A19: Pick up from Hotel 9:00 AM - Full day Sentosa Island Tour (1Way Cable Car +Madame Tussauds 5 In 1+ Wings Of Time) - Hotel Drop 8:30PM | B19: Today you are going to explore Sentosa Island by 9:00AM Start your adventure with a scenic - 1-way Cable Car ride offering stunning aerial views of Singapore. On Sentosa, dive into the world of fame at Madame Tussauds 5-in-1 – - featuring wax figures, - the Spirit of Singapore boat ride, - Images of Singapore LIVE, - Marvel 4D Cinema, and - the Ultimate Film Star Experience. - Wrap up your day with Wings of Time a breath taking night show. Then you will be dropped off to your hotel by 8:30PM
A20: Pick up from Hotel 9:00 AM - Full day Sentosa Island Tour (2Way Cable Car + Siloso Beach + Wings Of Time) - Hotel Drop 8:30PM | B20: After taking your break fast be ready to your exploration day with Sentosa Tour here you can enjoy: - Enjoy a 2-way Cable Car ride with stunning views of Singapore’s skyline and Sentosa’s lush landscape. - Spend a relaxing afternoon at Siloso Beach, perfect for sunbathing, beach games, or grabbing a bite by the sea. - As the day ends, be amazed by Wings of Time – a spectacular outdoor night show featuring lights, water, lasers, and fireworks, set against the open sea. - A perfect mix of scenic views, beach fun, and evening magic! Then you will be dropped off to your hotel by 8:30PM
A21: Pick up From Hotel 9:00 AM - Full Day Sentosa Island Tour ( 1 Way Cable Car + Luge and Sky Ride + Wings Of Time) - Hotel Drop 8:30PM | B21: · After taking your breakfast be ready our tour guide will pick up you by 9:00AM towards your next exploration to Sentosa Saver.at there you can explore: - You are going through Cable car to the island - Then enjoy with your Luge & Sky rides - Then you can take a lunch by your own - Then you can relax at the Siloso beach - In the evening you can enjoy Wings of Time show by 7:40 PM • Then you will be picked up from your pick up point towards your hotel by 8:30 PM
A22: Pick up From Hotel 11:00 AM - Half day City Tour with Singapore Flyer - Hotel Drop 2:00PM | B22: •Afret Taking your breakfast be ready to explore Singapore City by 11:00AM our vahical will take you for Singapore City tour at there you can see: - Merlion Park - Chinatown - Little India - Lunch at a hawker center by your own - Orchard Road • Then by 2:00PM you will be dropped off to your hotel. Now You Can enjoy hotel poolside or walk around near by market
... A44: Pick up From Hotel 9:00 AM - Gardens by the bay + Marina Bay Sands Sky Park - Hotel Drop 4:00PM | B44: ● After breakfast our Vahical will pick you up by 9:00AM and start with you on your journey Visit Gardens by the Bay (Cloud Forest & Flower Dome). ● Cloud Forest: - Mist –filled tropical mountain climate - Features as 35-meter indoor waterfall - Lush vegetation from tropical highlands - A walk along elevated walkways and cloud walk ● Flower Dome: - World’s largest glass greenhouse - Features a cool-dry climate - Showcase plants from Mediterranean and semi-arid regions - Themed floral displays that change seasonally. ● Then Visit Marina Bay Sands sky Park Observation Deck: - For a panoramic night skyline views ● Then you will be dropped off to your Hotel by 5:00 PM.

Sheet Table 3
A1: Meeting Point
A3: AIRPORT | B3: INTERNATIONAL ARRIVAL | C3: DOMESTIC ARRIVAL
A4: HO CHI MINH | B4: ARRIVAL PILLAR - 10 GF | C4: ARRIVAL HALL- A1
A5: HANOI | B5: T2 - GATE A & GATE B | C5: T1 - GATE A,B,E
A6: DANANG | B6: GATE 5 | C6: GATE 5
A7: PHU QUOC | B7: Exit Gate | C7: Exit Gate
A9: Terms & Conditions | Advisory Notes
A10: Arrival Notes:
A11: ➢ On the starting day of Tour, Once client local vietnameese number received then WhatsApp group will be created by us, kindly use that for any further communication.
A12: ➢ Guest need to proceed to the Arrival Or Exit Gate & look for airport representative with guest name on Pla card.
A13: ➢ Customer need to wait for 10-15 minutes at the arrival gate once they meet our Airport Representative, Because car park at parking point.
A14: ➢ The maximum waiting period is 90 mins from time of flight landing.
A15: ➢ All Tours and Transfer max waiting period is 10 min SIC basis and 30 Min on PVT Basis.
A16: ➢ Guest need to take care of their belongings while leaving Hotel or Car, We will not be responsible for any belongings.
A18: Hotel Notes:
A19: ➢ Standard Check in Time: 02:00 Pm *Early check in is subject to hotel availability & hotel may charge directly to the guest.
A20: ➢ Standard Check out Time: 11:00 Am Late checkout subject to hotel availability & hotel may charge directly to the guest.
A21: ➢ Hotel may ask for SECURITY DEPOSIT up to 200 USD Or Passport depends on the hotels policy.
... A27: ➢ For Visit to Island, all guest are advised to carry extra pair of clothes, towel and slippers.
