Workbook

Sheet Table 2
A2: Travel Itinerary
A3: Quote No. : | B3: Client Name : Contact Number: | E3: Travel Date : 27 Dec 2025
A4: Arrival Date : 27 Dec 2025 | B4: Guest Name : -- Guest Number : -- | E4: Total Person = 3 | F4: 3
A5: Departure Date : 8 Jan 2026 | B5: Transport : 7 Seater Private Car | E5: 12 Nights / 13 Days
A6: PLACE | B6: 4 STAR HOTEL NAME ( Not Booked ) ( With Breakfast ) | E6: PERIOD OF STAY
A7: HO CHI MINH | B7: Authentic Hanoi Boutique Hotel (Deluxe with window external view) | E7: 27 Dec / Nights | F7: 1 | G7: =VLOOKUP(B7,[1]Sheet4!F:G,2,FALSE) -> 73.333333 | H7: =G7*F7 -> 73.333333 | I7: =H7/2 -> 36.666667
A8: HANOI | B8: Authentic Hanoi Boutique Hotel (Deluxe with window external view) | E8: 28 Dec / Nights | F8: 3 | G8: =VLOOKUP(B8,[1]Sheet4!F:G,2,FALSE) -> 73.333333 | H8: =G8*F8 -> 220 | I8: =H8/2 -> 110
E9: 31 Dec / Nights | F9: 1 | G9: =VLOOKUP(B9,[1]Sheet4!F:G,2,FALSE) -> 0 | H9: =G9*F9 -> 0 | I9: =H9/2 -> 0
E10: 1 January / Nights | F10: 3 | G10: =VLOOKUP(B10,[1]Sheet4!F:G,2,FALSE) -> 0 | H10: =G10*F10 -> 0 | I10: =H10/2 -> 0 | L10: 24947
E11: 4 January / Nights | F11: 3 | G11: =VLOOKUP(B11,[1]Sheet4!F:G,2,FALSE) -> 0 | H11: =G11*F11 -> 0 | I11: =H11/2 -> 0 | L11: 23046
E12: 7 January / Nights | F12: 1 | G12: =VLOOKUP(B12,[1]Sheet4!F:G,2,FALSE) -> 0 | H12: =G12*F12 -> 0 | I12: =H12/2 -> 0
A13: PLACE | B13: 5 STAR HOTEL NAME ( Not Booked ) ( With Breakfast ) | E13: PERIOD OF STAY | J13: =SUM(I8,I10,I11,I12,I7,I9) -> 146.66667
E14: 17 March / Nights | G14: 0 | H14: =G14*F14 -> 0 | I14: =H14/2 -> 0
E15: 20 March / Nights | G15: 0 | H15: =G15*F15 -> 0 | I15: =H15/2 -> 0
E16: 23 March / Nights | G16: 0 | H16: =G16*F16 -> 0 | I16: =H16/2 -> 0
E17: 25 March / Nights | G17: 0 | H17: =G17*F17 -> 0 | I17: =H17/2 -> 0
G18: 0 | H18: =G18*F18 -> 0 | I18: =H18/2 -> 0 | J18: =SUM(I14,I15,I16,I17,I18) -> 0
A19: PLACE | B19: 3 STAR HOTEL NAME ( Not Booked ) ( With Breakfast ) | E19: PERIOD OF STAY | I19: =H19/2 -> 0
B20: Cruise | E20: 15 January / Nights | F20: 2 | G20: =VLOOKUP(B20,[1]Sheet4!M:N,2,FALSE) -> 0 | H20: =G20*F20 -> 0 | I20: =H20/2 -> 0
B21: Cruise | E21: 16 January / Nights | F21: 2 | G21: =VLOOKUP(B21,[1]Sheet4!M:N,2,FALSE) -> 0 | H21: =G21*F21 -> 0 | I21: =H21/2 -> 0
B22: Cruise | E22: 17 January / Nights | F22: 1 | G22: =VLOOKUP(B22,[1]Sheet4!M:N,2,FALSE) -> 0 | H22: =G22*F22 -> 0 | I22: =H22/2 -> 0
B23: Cruise | E23: 18 January / Nights | F23: 1 | G23: =VLOOKUP(B23,[1]Sheet4!M:N,2,FALSE) -> 0 | H23: =G23*F23 -> 0 | I23: =H23/2 -> 0 | J23: =SUM(I20,I21,I22,I23) -> 0
A24: Day -Date ( Approx ) | B24: Pick-Up Time | C24: Pick-Up Point | D24: Guide | E24: Tour/Tranasfer program | F24: Meal | G24: Guide/Person | H24: Tour Program | I24: Meal | J24: Car Rate/Person
E25: --- | F25: N\A | G25: =VLOOKUP(D25,Sheet2!H:I,2,FALSE) -> 0 | H25: =VLOOKUP(E25,Sheet2!A:B,2,FALSE) -> 0 | I25: =VLOOKUP(F25,Sheet2!L:M,2,FALSE) -> 0 | J25: =VLOOKUP(E25,Sheet2!A:C,3,FALSE) -> 0
E26: --- | F26: N\A | G26: =VLOOKUP(D26,Sheet2!H:I,2,FALSE) -> 0 | H26: =VLOOKUP(E26,Sheet2!A:B,2,FALSE) -> 0 | I26: =VLOOKUP(F26,Sheet2!L:M,2,FALSE) -> 0 | J26: =VLOOKUP(E26,Sheet2!A:C,3,FALSE) -> 0
E27: --- | F27: N\A | G27: =VLOOKUP(D27,Sheet2!H:I,2,FALSE) -> 0 | H27: =VLOOKUP(E27,Sheet2!A:B,2,FALSE) -> 0 | I27: =VLOOKUP(F27,Sheet2!L:M,2,FALSE) -> 0 | J27: =VLOOKUP(E27,Sheet2!A:C,3,FALSE) -> 0
E28: --- | F28: N\A | G28: =VLOOKUP(D28,Sheet2!H:I,2,FALSE) -> 0 | H28: 0 | I28: =VLOOKUP(F28,Sheet2!L:M,2,FALSE) -> 0 | J28: 0
E29: --- | F29: N\A | G29: =VLOOKUP(D29,Sheet2!H:I,2,FALSE) -> 0 | H29: 0 | I29: =VLOOKUP(F29,Sheet2!L:M,2,FALSE) -> 0 | J29: 0
E30: --- | F30: N\A | G30: =VLOOKUP(D30,Sheet2!H:I,2,FALSE) -> 0 | H30: =VLOOKUP(E30,Sheet2!A:B,2,FALSE) -> 0 | I30: =VLOOKUP(F30,Sheet2!L:M,2,FALSE) -> 0 | J30: =VLOOKUP(E30,Sheet2!A:C,3,FALSE) -> 0
E31: --- | F31: N\A | G31: =VLOOKUP(D31,Sheet2!H:I,2,FALSE) -> 0 | H31: =VLOOKUP(E31,Sheet2!A:B,2,FALSE) -> 0 | I31: =VLOOKUP(F31,Sheet2!L:M,2,FALSE) -> 0 | J31: =VLOOKUP(E31,Sheet2!A:C,3,FALSE) -> 0
E32: --- | F32: N\A | G32: =VLOOKUP(D32,Sheet2!H:I,2,FALSE) -> 0 | H32: =VLOOKUP(E32,Sheet2!A:B,2,FALSE) -> 0 | I32: =VLOOKUP(F32,Sheet2!L:M,2,FALSE) -> 0 | J32: =VLOOKUP(E32,Sheet2!A:C,3,FALSE) -> 0
E33: --- | F33: N\A | G33: =VLOOKUP(D33,Sheet2!H:I,2,FALSE) -> 0 | H33: =VLOOKUP(E33,Sheet2!A:B,2,FALSE) -> 0 | I33: =VLOOKUP(F33,Sheet2!L:M,2,FALSE) -> 0 | J33: =VLOOKUP(E33,Sheet2!A:C,3,FALSE) -> 0
E34: --- | F34: N\A | G34: =VLOOKUP(D34,Sheet2!H:I,2,FALSE) -> 0 | H34: =VLOOKUP(E34,Sheet2!A:B,2,FALSE) -> 0 | I34: =VLOOKUP(F34,Sheet2!L:M,2,FALSE) -> 0 | J34: =VLOOKUP(E34,Sheet2!A:C,3,FALSE) -> 0
E35: --- | F35: N\A | G35: =VLOOKUP(D35,Sheet2!H:I,2,FALSE) -> 0 | H35: =VLOOKUP(E35,Sheet2!A:B,2,FALSE) -> 0 | I35: =VLOOKUP(F35,Sheet2!L:M,2,FALSE) -> 0 | J35: =VLOOKUP(E35,Sheet2!A:C,3,FALSE) -> 0
E36: --- | F36: N\A | G36: =VLOOKUP(D36,Sheet2!H:I,2,FALSE) -> 0 | H36: =VLOOKUP(E36,Sheet2!A:B,2,FALSE) -> 0 | I36: =VLOOKUP(F36,Sheet2!L:M,2,FALSE) -> 0 | J36: =VLOOKUP(E36,Sheet2!A:C,3,FALSE) -> 0
E37: --- | F37: N\A | G37: =VLOOKUP(D37,Sheet2!H:I,2,FALSE) -> 0 | H37: =VLOOKUP(E37,Sheet2!A:B,2,FALSE) -> 0 | I37: =VLOOKUP(F37,Sheet2!L:M,2,FALSE) -> 0 | J37: =VLOOKUP(E37,Sheet2!A:C,3,FALSE) -> 0
E38: --- | F38: N\A | G38: =VLOOKUP(D38,Sheet2!H:I,2,FALSE) -> 0 | H38: =VLOOKUP(E38,Sheet2!A:B,2,FALSE) -> 0 | I38: =VLOOKUP(F38,Sheet2!L:M,2,FALSE) -> 0 | J38: =VLOOKUP(E38,Sheet2!A:C,3,FALSE) -> 0
E39: --- | F39: N\A | G39: =VLOOKUP(D39,Sheet2!H:I,2,FALSE) -> 0 | H39: =VLOOKUP(E39,Sheet2!A:B,2,FALSE) -> 0 | I39: =VLOOKUP(F39,Sheet2!L:M,2,FALSE) -> 0 | J39: =VLOOKUP(E39,Sheet2!A:C,3,FALSE) -> 0
E40: --- | F40: N\A | G40: =VLOOKUP(D40,Sheet2!H:I,2,FALSE) -> 0 | H40: =VLOOKUP(E40,Sheet2!A:B,2,FALSE) -> 0 | I40: =VLOOKUP(F40,Sheet2!L:M,2,FALSE) -> 0 | J40: =VLOOKUP(E40,Sheet2!A:C,3,FALSE) -> 0
E41: --- | F41: N\A | G41: =VLOOKUP(D41,Sheet2!H:I,2,FALSE) -> 0 | H41: =VLOOKUP(E41,Sheet2!A:B,2,FALSE) -> 0 | I41: =VLOOKUP(F41,Sheet2!L:M,2,FALSE) -> 0 | J41: =VLOOKUP(E41,Sheet2!A:C,3,FALSE) -> 0
...

Sheet Sheet2
A1: Hanoi Airport - Hanoi Hotel drop | C1: 19
A2: Hanoi Airport - Hanoi - 4 Hour Hanoi City Tour (HCM Complex + One piller pagoda + Old quarter shopping market + Train Street) - Hanoi Hotel drop | B2: 6 | C2: 54
A3: Hanoi Airport - Hanoi - 4 Hour Hanoi City Tour (HCM Complex + One piller pagoda + Old quarter shopping market + Train Street)- 50 Min Cyclo Tour - Hanoi Hotel Drop | B3: 9 | C3: 54
A4: Hanoi Airport - Hanoi - 4 Hour Hanoi City Tour (HCM Complex + One piller pagoda + Old quarter shopping market + Train Street)- 50 Min Cyclo Tour - Water Puppet Show - Hanoi Hotel Drop | B4: 19 | C4: 54
A5: Hanoi Airport - Hanoi - 4 Hour Hanoi City Tour (HCM Complex + One piller pagoda + Old quarter shopping market + Train Street) - Water Puppet Show - Hanoi Hotel Drop | B5: 14 | C5: 54
A6: Hanoi Hotel - Full Day Hanoi City Tour - Hotel Drop | B6: 6 | C6: 83
A7: Hanoi Hotel - 4 Hours Hanoi City Tour (HCM Complex + One piller pagoda + Old quarter shopping market + Train Street) - Hotel Drop | B7: 6 | C7: 35
A8: Hanoi Airport - 100 KM 2 hours - Ninh Binh Tour - Trang An River boat ride with three caves - Hotel Drop | B8: 13 | C8: 113
A9: Hanoi Airport - 100 KM 2 hours - Ninh Binh Tour (With Lunch)- Trang An River boat ride with three caves - Hotel Drop | B9: 29 | C9: 113
A10: Hanoi Hotel - 100 KM 2 hours - Ninh Binh Tour - Trang An River boat ride with three caves - Hotel Drop | B10: 13 | C10: 94
A11: Hanoi Hotel - 100 KM 2 hours - Ninh Binh Tour (With Lunch) - Trang An River boat ride with three caves - Hotel Drop | B11: 29 | C11: 94 | H11: No | I11: 0 | L11: D | M11: 17
A12: Hanoi Airport - 200 Km 4 hours drive - Halong bay- 11:30 AM need to reach at Halong bay for cruise depart | C12: 182 | H12: Yes | I12: 40 | L12: L,D | M12: 34
A13: Hanoi Hotel - 200 Km 4 hours drive - Halong bay- 11:30 AM need to reach at Halong bay for cruise depart | C13: 182 | H13: 0 | I13: 0 | L13: Local L,Local D | M13: 0
A14: Hanoi Hotel - 200 Km 4 hours drive - Halong bay day cruise - 11:30 AM need to reach at Halong bay for cruise depart - 200 Km 4 hours drive - Hanoi Hotel Drop | B14: 47 | C14: 140 | L14: Local L | M14: 0
A15: Halong Bay - Hanoi 4 hour 200 km Drive - Hanoi Hotel drop | C15: 0 | L15: Local L,D | M15: 17
A16: Halong Bay - Hanoi 4 hour 200 km Drive - Hanoi - 4 hours Hanoi City Tour - Hanoi Hotel drop | B16: 6 | C16: 35 | L16: Local Br,D | M16: 17
A17: Halong Bay - Hanoi 4 hour 200 km Drive - Hanoi Airport drop | C17: 0 | L17: Local Br | M17: 0
A18: Hanoi Airport - 300KM 6 hour Sapa - Sapa Hotel Drop (1 Night) | C18: 338 | L18: L | M18: 17
A19: Hanoi Airport - 300KM 6 hour Sapa - Sapa Hotel Drop (2 Nights) | C19: 338 | L19: Br | M19: 0
A20: Hanoi Airport - 300KM 6 hour Sapa - Sapa Hotel Drop (3 Nights) | C20: 676 | L20: Br,D | M20: 17
A21: Hanoi Hotel - 300KM 6 hour Sapa - Sapa Hotel Drop (1 Night) | C21: 338 | L21: (B,L,D) Limited Indian Food | M21: 0
A22: Hanoi Hotel - 300KM 6 hour Sapa - Sapa Hotel Drop (2 Nights) | C22: 338 | L22: N\A | M22: 0
A23: Hanoi Hotel - 300KM 6 hour Sapa - Sapa Hotel Drop (3 Nights) | C23: 676
A24: Hanoi Airport - 300KM 6 hour Sapa - Moana Sculpture - Sapa Hotel Drop | B24: 8
A25: Hanoi Airport - 300KM 6 hour Sapa - Cat Cat Village Tour - Sapa Hotel Drop | B25: 10
A26: Hanoi Airport - 300KM 6 hour Sapa - Glass Bottom Bridge - Sapa Hotel Drop | B26: 26
A27: Hanoi Hotel - 300KM 6 hour Sapa - Moana Sculpture - Cat Cat Village tour - Sapa Hotel Drop | B27: 18
A28: Sapa Hotel - Moana Sculpture - Cat Cat Village tour - Sapa Hotel Drop | B28: 18
A29: Sapa Hotel - Moana Sculpture - Sapa Hotel Drop | B29: 8
A30: Sapa Hotel - Cat Cat Village tour - Sapa Hotel Drop | B30: 10
A31: Sapa Hotel - Fansipan Mountain - Glass Bottom Bridge - 300km 6 hour drive - Hanoi Hotel drop | B31: 88
A32: Sapa Hotel - Fansipan Mountain - 300km 6 hour drive - Hanoi Hotel drop | B32: 62
A33: Sapa Hotel - Glass Bottom Bridge - 300km 6 hour drive - Hanoi Hotel drop | B33: 26
A34: Sapa Hotel - Fansipan Mountain - Glass Bottom Bridge - Sapa Hotel drop | B34: 88
A35: Sapa Hotel - Fansipan Mountain - Sapa Hotel drop | B35: 62
A36: Sapa Hotel - Glass Bottom Bridge - Sapa Hotel drop | B36: 26
A37: Hanoi Hotel - Hanoi Airport Drop | C37: 0
A38: Sapa Hotel - 300 KM 6 hours Drive - Hanoi Hotel Drop | C38: 15
A39: Sapa Hotel - 300 KM 6 hours Drive - Hanoi - Hanoi Airport Drop | C39: 0
A41: Danang Airport - Danang Hotel Drop | C41: 9
...

Sheet Sheet4
F1: HANOI | J1: HANOI | M1: HANOI
F2: 4 star | J2: 5 STAR | M2: 3 STAR
A3: HOTEL NAME (Room Category) | B3: PRICE | F3: The Q hotel Ha Noi ( Superior ) | G3: =E6 -> 71.041667 | J3: GRAND VISTA HANOI HOTEL (Premium Suite) | K3: =E33 -> 0 | M3: BRILLIANT HANOI HOTEL (Deluxe No window) | N3: =E21 -> 50.416667
A4: HANOI | B4: PRICE | D4: 0 | E4: 0 | F4: The Q hotel Ha Noi ( Deluxe ) | G4: =E7 -> 77.916667 | J4: GRAND VISTA HANOI HOTEL (Executive Suite) | K4: =E34 -> 84.791667 | M4: BRILLIANT HANOI HOTEL (Junior Window City View) | N4: =E22 -> 64.166667
A5: 4 star | D5: =(B5/24000) -> 0 | E5: =D5+D5*10% -> 0 | F5: Rex Hanoi Hotel (superior No window ) | G5: =E8 -> 68.75 | J5: Apricot Hotel ( SKETCH Room ) | K5: =E35 -> 132.91667 | M5: HANOI ANISE HOTEL & SPA (Superior TW/DBL) | N5: =E23 -> 32.083333
A6: The Q hotel Ha Noi ( Superior ) | B6: 1550000 | D6: =(B6/24000) -> 64.583333 | E6: =D6+D6*10% -> 71.041667 | F6: Rex Hanoi Hotel (Deluxe internal window) | G6: =E9 -> 77.916667 | J6: Apricot Hotel (CANVAS Room) | K6: =E36 -> 114.58333 | M6: HANOI ANISE HOTEL & SPA ( Deluxe City View TW/DBL) | N6: =E24 -> 36.666667
A7: The Q hotel Ha Noi ( Deluxe ) | B7: 1700000 | D7: =(B7/24000) -> 70.833333 | E7: =D7+D7*10% -> 77.916667 | F7: NESTA HOTEL - WEST LAKE (Deluxe City View ) | G7: =E10 -> 59.583333 | J7: PAN PACIFIC HANOI (Deluxe Room) | K7: =E37 -> 165 | M7: DIAMOND LEGEND HOTEL (Superior Room window inside) | N7: =E25 -> 29.791667
A8: Rex Hanoi Hotel (superior No window ) | B8: 1500000 | D8: =(B8/24000) -> 62.5 | E8: =D8+D8*10% -> 68.75 | F8: NESTA HOTEL - WEST LAKE (Deluxe Lake View) | G8: =E11 -> 64.166667 | J8: PAN PACIFIC HANOI (Premier Lake View Room) | K8: =E38 -> 192.5 | M8: DIAMOND LEGEND HOTEL (Deluxe Room Window or Balcony) | N8: =E26 -> 36.666667
A9: Rex Hanoi Hotel (Deluxe internal window) | B9: 1700000 | D9: =(B9/24000) -> 70.833333 | E9: =D9+D9*10% -> 77.916667 | F9: VICTORIA HOI AN BEACH RESORT & SPA ( Superior River View) | G9: =E12 -> 142.08333 | J9: LOTTE HOTEL ( Deluxe Room ) | K9: =E39 -> 159.5 | M9: Little Diamond Hotel Hanoi ( Superior Double no window) | N9: =E27 -> 25.208333
A10: NESTA HOTEL - WEST LAKE (Deluxe City View *) | B10: 1300000 | D10: =(B10/24000) -> 54.166667 | E10: =D10+D10*10% -> 59.583333 | F10: VICTORIA HOI AN BEACH RESORT & SPA ( Superior Garden View) | G10: =E13 -> 169.58333 | J10: LOTTE HOTEL ( Club Junior Suite) | K10: =E40 -> 231 | M10: Little Diamond Hotel Hanoi (Junior Double window inside) | N10: =E28 -> 29.791667
A11: NESTA HOTEL - WEST LAKE (Deluxe Lake View) | B11: 1400000 | D11: =(B11/24000) -> 58.333333 | E11: =D11+D11*10% -> 64.166667 | F11: Authentic Hanoi Boutique Hotel (Deluxe No window) | G11: =E14 -> 59.583333 | J11: Dolce by Wyndham Hanoi Golden Lake ( Golden Deluxe) | K11: =E41 -> 357.5 | M11: JaCosmo Hotel and Spa (Superior room) | N11: =E29 -> 41.25
A12: VICTORIA HOI AN BEACH RESORT & SPA ( Superior River View) | B12: 3100000 | D12: =(B12/24000) -> 129.16667 | E12: =D12+D12*10% -> 142.08333 | G12: =E15 -> 0 | J12: Dolce by Wyndham Hanoi Golden Lake (Golden Executive) | K12: =E42 -> 385 | M12: JaCosmo Hotel and Spa (Deluxe room) | N12: =E30 -> 45.833333
A13: VICTORIA HOI AN BEACH RESORT & SPA ( Superior Garden View) | B13: 3700000 | D13: =(B13/24000) -> 154.16667 | E13: =D13+D13*10% -> 169.58333 | F13: Authentic Hanoi Boutique Hotel (Deluxe with window external view) | G13: =E16 -> 73.333333 | J13: OAKWOOD RESIDENCE HANOI ( Studio Room) | K13: =E43 -> 93.729167
A14: Authentic Hanoi Boutique Hotel (Deluxe No window) | B14: 1300000 | D14: =(B14/24000) -> 54.166667 | E14: =D14+D14*10% -> 59.583333 | F14: The Hanoi Club Hotel & Residences (Superior (view phố) | G14: =E17 -> 91.666667 | J14: OAKWOOD RESIDENCE HANOI (Two Bed Room) | K14: =E44 -> 174.625 | M14: Cruise
D15: =(B15/24000) -> 0 | E15: =D15+D15*10% -> 0 | F15: The Hanoi Club Hotel & Residences ( Deluxe (view 1 phần hồ) | G15: =E18 -> 100.83333 | M15: ERA CRUISES ( Terrace Suite ) | N15: =E47 -> 367.58333
A16: Authentic Hanoi Boutique Hotel (Deluxe with window external view) | B16: 1600000 | D16: =(B16/24000) -> 66.666667 | E16: =D16+D16*10% -> 73.333333 | J16: Cruise | M16: ERA CRUISES (King Terrace Suite) | N16: =E48 -> 412.0875
A17: The Hanoi Club Hotel & Residences (Superior (view phố) | B17: 2000000 | D17: =(B17/24000) -> 83.333333 | E17: =D17+D17*10% -> 91.666667 | F17: Cruise | J17: ERA CRUISES ( Terrace Suite ) | K17: =E47 -> 367.58333 | M17: HẠ LONG BAY AQUAMARINE CRUISE (Junior Suite) | N17: =E49 -> 229.16667
A18: The Hanoi Club Hotel & Residences ( Deluxe (view 1 phần hồ) | B18: 2200000 | D18: =(B18/24000) -> 91.666667 | E18: =D18+D18*10% -> 100.83333 | F18: ERA CRUISES ( Terrace Suite ) | G18: =E47 -> 367.58333 | J18: ERA CRUISES (King Terrace Suite) | K18: =E48 -> 412.0875 | M18: HẠ LONG BAY AQUAMARINE CRUISE ( Senior Suite) | N18: =E50 -> 242.91667
D19: =(B19/24000) -> 0 | E19: =D19+D19*10% -> 0 | F19: ERA CRUISES (King Terrace Suite) | G19: =E48 -> 412.0875 | J19: HẠ LONG BAY AQUAMARINE CRUISE (Junior Suite) | K19: =E49 -> 229.16667 | M19: AMBASSADOR CRUISE (Executive Ambassador Balcony) | N19: =E51 -> 411.125
A20: 3 STAR | D20: =(B20/24000) -> 0 | E20: =D20+D20*10% -> 0 | F20: HẠ LONG BAY AQUAMARINE CRUISE (Junior Suite) | G20: =E49 -> 229.16667 | J20: HẠ LONG BAY AQUAMARINE CRUISE ( Senior Suite) | K20: =E50 -> 242.91667 | M20: AMBASSADOR CRUISE (Ambassador Balcony Suite) | N20: =E52 -> 443.4375
A21: BRILLIANT HANOI HOTEL (Deluxe No window) | B21: 1100000 | D21: =(B21/24000) -> 45.833333 | E21: =D21+D21*10% -> 50.416667 | F21: HẠ LONG BAY AQUAMARINE CRUISE ( Senior Suite) | G21: =E50 -> 242.91667 | J21: AMBASSADOR CRUISE (Executive Ambassador Balcony) | K21: =E51 -> 411.125 | M21: LA PANDORA CRUISE ( Suite Balcony) | N21: =E53 -> 24.75
A22: BRILLIANT HANOI HOTEL (Junior Window City View) | B22: 1400000 | D22: =(B22/24000) -> 58.333333 | E22: =D22+D22*10% -> 64.166667 | F22: AMBASSADOR CRUISE (Executive Ambassador Balcony) | G22: =E51 -> 411.125 | J22: AMBASSADOR CRUISE (Ambassador Balcony Suite) | K22: =E52 -> 443.4375 | M22: LA PANDORA CRUISE ( Family Suite Balcony) | N22: =E54 -> 26.583333
A23: HANOI ANISE HOTEL & SPA (Superior TW/DBL) | B23: 700000 | D23: =(B23/24000) -> 29.166667 | E23: =D23+D23*10% -> 32.083333 | F23: AMBASSADOR CRUISE (Ambassador Balcony Suite) | G23: =E52 -> 443.4375 | J23: LA PANDORA CRUISE ( Suite Balcony) | K23: =E53 -> 24.75 | M23: ALISA PREMIER CRUISE ( Junior suite) | N23: =E55 -> 289.575
A24: HANOI ANISE HOTEL & SPA ( Deluxe City View TW/DBL) | B24: 800000 | D24: =(B24/24000) -> 33.333333 | E24: =D24+D24*10% -> 36.666667 | F24: LA PANDORA CRUISE ( Suite Balcony) | G24: =E53 -> 24.75 | J24: LA PANDORA CRUISE ( Family Suite Balcony) | K24: =E54 -> 26.583333 | M24: ALISA PREMIER CRUISE (Senior Balcony Suite) | N24: =E56 -> 300.7125
A25: DIAMOND LEGEND HOTEL (Superior Room window inside) | B25: 650000 | D25: =(B25/24000) -> 27.083333 | E25: =D25+D25*10% -> 29.791667 | F25: LA PANDORA CRUISE ( Family Suite Balcony) | G25: =E54 -> 26.583333 | J25: ALISA PREMIER CRUISE ( Junior suite) | K25: =E55 -> 289.575 | M25: AQUAMARINE CRUISE (Junior Suite) | N25: =E57 -> 229.16667
A26: DIAMOND LEGEND HOTEL (Deluxe Room Window or Balcony) | B26: 800000 | D26: =(B26/24000) -> 33.333333 | E26: =D26+D26*10% -> 36.666667 | F26: ALISA PREMIER CRUISE ( Junior suite) | G26: =E55 -> 289.575 | J26: ALISA PREMIER CRUISE (Senior Balcony Suite) | K26: =E56 -> 300.7125 | M26: AQUAMARINE CRUISE (Senior Suite) | N26: =E58 -> 242.91667
A27: Little Diamond Hotel Hanoi ( Superior Double no window) | B27: 550000 | D27: =(B27/24000) -> 22.916667 | E27: =D27+D27*10% -> 25.208333 | F27: ALISA PREMIER CRUISE (Senior Balcony Suite) | G27: =E56 -> 300.7125 | J27: AQUAMARINE CRUISE (Junior Suite) | K27: =E57 -> 229.16667 | M27: SWAN CRUISES ( Deluxe Double/Twin) | N27: =E59 -> 245.20833
A28: Little Diamond Hotel Hanoi (Junior Double window inside) | B28: 650000 | D28: =(B28/24000) -> 27.083333 | E28: =D28+D28*10% -> 29.791667 | F28: AQUAMARINE CRUISE (Junior Suite) | G28: =E57 -> 229.16667 | J28: AQUAMARINE CRUISE (Senior Suite) | K28: =E58 -> 242.91667 | M28: SWAN CRUISES (Suite Cabins) | N28: =E60 -> 267.3
A29: JaCosmo Hotel and Spa (Superior room) | B29: 900000 | D29: =(B29/24000) -> 37.5 | E29: =D29+D29*10% -> 41.25 | F29: AQUAMARINE CRUISE (Senior Suite) | G29: =E58 -> 242.91667 | J29: SWAN CRUISES ( Deluxe Double/Twin) | K29: =E59 -> 245.20833 | M29: SENA CRUISE ( Balcony Deluxe ) | N29: =E61 -> 267.3
A30: JaCosmo Hotel and Spa (Deluxe room) | B30: 1000000 | D30: =(B30/24000) -> 41.666667 | E30: =D30+D30*10% -> 45.833333 | F30: SWAN CRUISES ( Deluxe Double/Twin) | G30: =E59 -> 245.20833 | J30: SWAN CRUISES (Suite Cabins) | K30: =E60 -> 267.3 | M30: RITA CRUISE (STANDARD CABIN) | N30: =E62 -> 256.66667
D31: =(B31/24000) -> 0 | E31: =D31+D31*10% -> 0 | F31: SWAN CRUISES (Suite Cabins) | G31: =E60 -> 267.3 | J31: SENA CRUISE ( Balcony Deluxe ) | K31: =E61 -> 267.3 | M31: RITA CRUISE (JUNIOR SUITE) | N31: =E63 -> 311.66667
A32: 5 STAR | B32: PRICE | D32: =(B32/24000) -> #VALUE! | E32: =D32+D32*10% -> #VALUE! | F32: SENA CRUISE ( Balcony Deluxe ) | G32: =E61 -> 267.3 | J32: RITA CRUISE (STANDARD CABIN) | K32: =E62 -> 256.66667 | M32: LE JOURNEY CRUISE | N32: =E64 -> 222.75
B33: 0 | D33: =(B33/24000) -> 0 | E33: =D33+D33*10% -> 0 | F33: RITA CRUISE (STANDARD CABIN) | G33: =E62 -> 256.66667 | J33: RITA CRUISE (JUNIOR SUITE) | K33: =E63 -> 311.66667 | M33: SENA CRUISE ( Balcony Executive ) | N33: =E65 -> 289.575
A34: GRAND VISTA HANOI HOTEL (DELUXE ROOM) | B34: 1850000 | D34: =(B34/24000) -> 77.083333 | E34: =D34+D34*10% -> 84.791667 | F34: RITA CRUISE (JUNIOR SUITE) | G34: =E63 -> 311.66667 | J34: LE JOURNEY CRUISE | K34: =E64 -> 222.75 | M34: HERA CLASSIC BOUTIQUE (Deluxe Cabin with Ocean View) | N34: =E66 -> 220
A35: Apricot Hotel ( SKETCH Room ) | B35: 2900000 | D35: =(B35/24000) -> 120.83333 | E35: =D35+D35*10% -> 132.91667 | F35: LE JOURNEY CRUISE | G35: =E64 -> 222.75 | J35: SENA CRUISE ( Balcony Executive ) | K35: =E65 -> 289.575 | M35: HERA CLASSIC BOUTIQUE (Executive Suite Cabin with private balcony) | N35: =E67 -> 247.5
A36: Apricot Hotel (CANVAS Room) | B36: 2500000 | D36: =(B36/24000) -> 104.16667 | E36: =D36+D36*10% -> 114.58333 | F36: SENA CRUISE ( Balcony Executive ) | G36: =E65 -> 289.575 | J36: HERA CLASSIC BOUTIQUE (Deluxe Cabin with Ocean View) | K36: =E66 -> 220 | M36: HERA GRAND LUXURY CRUISE (Junior Suite Cabin with Ocean View) | N36: =E68 -> 247.5
A37: PAN PACIFIC HANOI (Deluxe Room) | B37: 3600000 | D37: =(B37/24000) -> 150 | E37: =D37+D37*10% -> 165 | F37: HERA CLASSIC BOUTIQUE (Deluxe Cabin with Ocean View) | G37: =E66 -> 220 | J37: HERA CLASSIC BOUTIQUE (Executive Suite Cabin with private balcony) | K37: =E67 -> 247.5 | M37: HERA GRAND LUXURY CRUISE (Ocean Suite Cabin with private balcony) | N37: =E69 -> 293.33333
A38: PAN PACIFIC HANOI (Premier Lake View Room) | B38: 4200000 | D38: =(B38/24000) -> 175 | E38: =D38+D38*10% -> 192.5 | F38: HERA CLASSIC BOUTIQUE (Executive Suite Cabin with private balcony) | G38: =E67 -> 247.5 | J38: HERA GRAND LUXURY CRUISE (Junior Suite Cabin with Ocean View) | K38: =E68 -> 247.5 | M38: HERA BOUTIQUE (Deluxe Cabin with Ocean View) | N38: =E70 -> 201.66667
A39: LOTTE HOTEL ( Deluxe Room ) | B39: 3480000 | D39: =(B39/24000) -> 145 | E39: =D39+D39*10% -> 159.5 | F39: HERA GRAND LUXURY CRUISE (Junior Suite Cabin with Ocean View) | G39: =E68 -> 247.5 | J39: HERA GRAND LUXURY CRUISE (Ocean Suite Cabin with private balcony) | K39: =E69 -> 293.33333 | M39: HERA BOUTIQUE (Executive Suite Cabin with private balcony) | N39: =E71 -> 229.16667
A40: LOTTE HOTEL ( Club Junior Suite) | B40: 5040000 | D40: =(B40/24000) -> 210 | E40: =D40+D40*10% -> 231 | F40: HERA GRAND LUXURY CRUISE (Ocean Suite Cabin with private balcony) | G40: =E69 -> 293.33333 | J40: HERA BOUTIQUE (Deluxe Cabin with Ocean View) | K40: =E70 -> 201.66667 | M40: HERA GRAND LUXURY CRUISE (Junior Suite Cabin with Ocean View) | N40: =E72 -> 229.16667
...

Sheet Sheet1
D1: 5 * HOTEL | F1: International | I1: HANOI
D2: Hanoi Grand Plaza Hotel
D3: Grand Vista Hotel Hanoi | F3: Hanoi Airport ARRIVAL - T2 - PILLAR 10 1F Car pickup point. | I3: Hanoi Airport – 4 Hour Hanoi City Tour with guide - hotel - Dinner At Indian Restaurant - Hanoi Hotel drop (D)
D4: apricot hotel hanoi | F4: Halong Bay Cruise Terminal Dock | I4: Hnaoi Hotel - 100km 2 hours - Ninh Binh Tour - Tam Coc - Dinner At Indian Restaurant - Hotel Drop (B,D)
D5: Paradise Grand Cruise | F5: Danang Airport EXIT GATE PARKING Car pickup point. | I5: Hanoi Hotel - 200 Km 4 hours drive - Halong bay- 11:30 AM need to reach at Halong bay for cruise depart (B,Local L, Local D)
D6: TMS Hotel Da Nang Beach | F6: Ho Chi Minh Airport ARRIVAL - T2 - PILLAR 10 GF | I6: Halong Bay - Hanoi 4 hour 200 km - Dinner At Indian Restaurant - Hanoi Hotel drop, (B,Local Br,D)
D7: Four Points by Sheraton Danang | F7: Phu Quoc Airport EXIT GATE PARKING pickup point. | I7: Hanoi Hotel - HCM Complex - Tran Quoc Pagoda - Old Town 15 Min Tour - Cho Dong Xuan Market - Old Town For Shopping - Dinner At Indian Restaurant - Hanoi hotel drop (B,D)
F8: Siem Reap Airport Arrival Hall | I8: Hanoi Hotel - 300KM 6 hour Sapa - Moana Sculpture - Cat Cat Village tour - Dinner At Indian Restaurant - Sapa Hotel Drop (B,D)
D9: Equatorial Ho Chi Minh City | I9: Sapa Hotel - Fansipan Mountain with guide - 300km 6 hour drive - Dinner At Indian Restaurant - Hanoi Hotel drop (B,D)
D10: Sol by Meliá Phu Quoc | F10: Domestic | I10: Hanoi Hotel - Hanoi Airport Drop, Flight to --- (B) Vietjet Air VJ --- --- Departure
D12: 4 * Hotels | F12: Hanoi Airport T1 - ARRIVAL - E2 Car pickup point. | I12: DANANG
D13: Rex Hanoi Hotel | F13: Halong Bay Cruise Terminal Dock | I13: Danang Airport - Dinner At Indian Restaurant - Danang Hotel Drop (D)
A14: Arrival Date : January, 2024 | D14: Nesta West Lake Hotel Hanoi | F14: Danang Airport T1 ARRIVAL PILLAR 4,5 Car pickup point. | I14: Danang hotel - Ba Na Hills with guide - Dinner At Indian Restaurant - Danang hotel (B,D)
A15: Arrival Date : February, 2024 | D15: Le Journey Luxury Cruise | F15: Ho Chi Minh Airport T1 - ARRIVAL - A1 | I15: Danang hotel - Marble Mountain - Hoi An Ancient Town - Japanese Covered Bridge - Dinner At Indian Restaurant - Hotel Drop (B,D)
A16: Arrival Date : March, 2024 | D16: Hera Cruise | F16: Phu Quoc Airport EXIT GATE PARKING pickup point. | I16: Danang hotel - Coconut Village with guide - Basket Boat Ride - Hoi An Ancient Town Tour - Lantern Release On The River - Dinner At Indian Restaurant - Danang hotel Drop, 8:30 PM (B,D)
A17: Arrival Date : April, 2024 | D17: Stella Maris Beach Danang Hotel | F17: Siem Reap Airport Arrival Hall | I17: Danang Hotel - Danang Airport Drop, Flight to ---- (B) Vietjet Air VJ --- --- Departure
A18: Arrival Date : May, 2024 | D18: Golden Lotus Luxury Hotel Da Nang
A19: Arrival Date : June, 2024 | D19: Bay Hotel Ho Chi Minh | I19: HO CHI MINH
A20: Arrival Date : July, 2024 | D20: ramada encore ho chi minh | I20: Ho Chi Minh Airport - Dinner At Indian Restaurant - Ho Chi Minh Hotel Drop (D)
A21: Arrival Date : August, 2024 | D21: vinpearl resort and spa | I21: Ho Chi Minh Hotel - HCM city tour - Lunch Transfer - Notre Dame Cathedral, General Post Office, The city hall, Opera House - Reunification Hall - War Remnants Museum - Hop on Hop off city tour - Dinner At Indian Restaurant - Hotel Drop (B,D)
A22: Arrival Date : September, 2024 | I22: Ho Chi Minh Hotel - Mekong Delta (My Tho) with guide - Dinner At Indian Restaurant - HCM hotel drop (B,D)
A23: Arrival Date : October, 2024 | D23: 3 * Hotels | I23: HCM Hotel - Cu Chi Tunnel Tour with guide - Dinner At Indian Restaurant - hotel drop (B,D)
A24: Arrival Date : November, 2024 | D24: Diamond Legend Hotel | I24: HCM Hotel - HCM Airport Drop, Flight to ---- (B) Vietjet Air VJ --- --- Departure
A25: Arrival Date : December, 2024 | D25: Le Journey Classic Cruise
D26: Golden Lotus Grand Hotel | I26: PHU QUOC
A27: Departure Date : January, 2024 | D27: Ben Thanh Boutique Hotel | I27: Phu Quoc Airport - Dinner At Indian Restaurant - Phu Quoc Hotel Drop (D)
A28: Departure Date : February, 2024 | D28: Resort Arcadia Phú Quốc | I28: Phu Quoc Hotel - Vin Pearl Safari & Vin Wonders - 6 Theme park - Dinner At Indian Restaurant - Hotel Drop (B,D)
A29: Departure Date : March, 2024 | I29: Phu Quoc Hotel - Full Day - 3 Island tour in south by speedboat - Dinner At Indian Restaurant - Late Noon return hotel drop (B,D)
A30: Departure Date : April, 2024 | E30: Transport : 4 Seater Private Car | I30: Phu Quoc Hotel - Phu Quoc Airport Drop, Flight to --- (B) Vietjet Air VJ --- --- Departure
A31: Departure Date : May, 2024 | E31: Transport : 7 Seater Private Car
A32: Departure Date : June, 2024 | E32: Transport : 16 Seater Private Car | I32: SIEM REAP
A33: Departure Date : July, 2024 | E33: Transport : 29 Seater Private Car | I33: Siem Reap Airport - Hotel - Apsara Dance Show Dinner At Restaurant - Siem Reap Hotel Drop (D)
A34: Departure Date : August, 2024 | E34: Transport : 45 Seater Private Car | I34: Siem Reap Hotel - Angkor Temple tour with guide - Dinner At Indian Restaurant - Hotel Drop (B,D)
A35: Departure Date : September, 2024 | I35: Siem Reap Hotel - Floating village with guide - Dinner At Indian Restaurant - Hotel Drop (B,D)
A36: Departure Date : October, 2024 | I36: Siem Reap Hotel - Siem Reap Airport Drop (B)
A37: Departure Date : November, 2024
A38: Departure Date : December, 2024 | I38: PHNOM PENH
I39: Siem Reap Hotel - Drive By Car - Dinner At Indian Restaurant - Phnom Penh Hotel Drop (B,D)
I40: Phnom Penh Hotel - Royal Palace and Silver Pagoda with guide - National Museum and Tuol Sleng Museum - Choeung Ek - Market By Own - Dinner At Indian Restaurant - Hotel Drop (B,D)
I41: Phnom Penh Hotel - Phnom Penh Airport Drop (B)

Sheet Sheet3
A1: Hanoi Airport - Hanoi Hotel drop | B1: ● ARRIVAL HANOI, VIETNAM ♦ Arrive In Noi Bai International Airport. ♦ Our Private Car Will Pick You Up From The Airport And Head Towards The Hotel. ♦ Early Check-in is not included . Take Necessary Rest After Flight. ♦ Overnight stay in Hanoi.
A2: Hanoi Airport - Hanoi - 4 Hour Hanoi City Tour - Hanoi Hotel drop | B2: ● ARRIVAL HANOI - HANOI CITY TOUR, VIETNAM ♦ Arrive In Noi Bai International Airport. ♦ Our Private Car Will Pick You Up From The Airport And Head Towards The Hotel. ♦ Early Check-in is not included. Take Necessary Rest After Flight ♦ Check Out The Old Street Quarter For Hanoi City Tour – Visit The Temple of Literature, Vietnam’s first university, Hoan Kiem Lake & Ly Thai Statue, HCM Complex: Ho Chi Minh Mausoleum, One pillar Pagoda, Ba Dinh Square. ♦ 4 Hours tour then Check in Hotel. ♦ Overnight stay in Hanoi.
A3: Hanoi Airport - Hanoi - 4 Hour Hanoi City Tour - 50 Min Cyclo Tour - Hanoi Hotel Drop | B3: ● ARRIVAL HANOI - HANOI CITY TOUR - 50 MIN CYCLO TOUR, VIETNAM ♦ Arrive In Noi Bai International Airport. ♦ Our Private Car Will Pick You Up From The Airport And Head Towards The Hotel. ♦ Early Check-in is not included. Take Necessary Rest After Flight ♦ Check Out The Old Street Quarter For 4 hour Hanoi City Tour , 50 Min Cyclo Tour. ♦ After tour Check in Hotel. ♦ Overnight stay in Hanoi.
A4: Hanoi Airport - Hanoi - 4 Hour Hanoi City Tour - 50 Min Cyclo Tour - Water Puppet Show - Hanoi Hotel Drop | B4: ● ARRIVAL HANOI - HANOI CITY TOUR - 50 MIN CYCLO TOUR - WATER PUPPET SHOW, VIETNAM ♦ Arrive In Noi Bai International Airport. ♦ Our Private Car Will Pick You Up From The Airport And Head Towards The Hotel. ♦ Early Check-in is not included. Take Necessary Rest After Flight Check Out The Old Street Quarter For 4 hours Hanoi City Tour, 50 Min Cyclo Tour, Water Puppet Show. ♦ After tour Check in Hotel. ♦ Overnight stay in Hanoi.
A5: Hanoi Airport - Hanoi - 4 Hour Hanoi City Tour - Water Puppet Show - Hanoi Hotel Drop | B5: ● ARRIVAL HANOI - HANOI CITY TOUR - WATER PUPPET SHOW, VIETNAM ♦ Arrive In Noi Bai International Airport. ♦ Our Private Car Will Pick You Up From The Airport And Head Towards The Hotel. ♦ Check Into The Hotel, Take Necessary Rest After Flight Check Out The Old Street Quarter For 4 hour Hanoi City Tour, Water Puppet Show. ♦ After tour Check in Hotel. ♦ Overnight stay in Hanoi.
A6: Hanoi Hotel - Full Day Hanoi City Tour - Hotel Drop | B6: ● FULL DAY - HANOI CITY TOUR ♦ After breakfast, at 08:30 in the morning, our tour guide will pick you up and start with you on your journey to Full Day Hanoi City Tour driving per way for transfer. ♦ Visit Hanoi City Tour – Visit The Temple of Literature, Vietnam’s first university, Hoan Kiem Lake & Ly Thai Statue, HCM Complex: Ho Chi Minh Mausoleum, One pillar Pagoda, Ba Dinh Square. ♦ Evening come back to hotel, Overnight Stay in Hanoi.
A7: Hanoi Hotel - 4 Hours Hanoi City Tour - Hotel Drop | B7: ● HALF DAY - HANOI CITY TOUR ♦ After breakfast, at 08:30 in the morning, our tour guide will pick you up and start with you on your journey to Half day Hanoi City Tour driving per way for transfer. ♦ Visit Hanoi City Tour. ♦ Evening come back to hotel, Free Time For Shopping. Overnight Stay in Hanoi.
A8: Hanoi Airport - 100 KM 2 hours - Ninh Binh Tour - Tam Coc - Hotel Drop | B8: ● FULL DAY – NINH BINH TOUR ♦ (100 KM 2 hours Drive) ♦ Arrive In Noi Bai International Airport. ♦ Our Private Car Will Pick You Up From The Airport And Head Towards The Depart For Ninh Binh Province ♦ Have A Short Break For 15 _ 20 Minutes To Relax ♦ Visit Hoa Lu, Ancient Capital Of Vietnam Between 968 And 1010. You Have A Chance To Learn About Vietnamese History In The Feudal System Under Dinh, Le, And Ly Dynasty ♦ Visit Tam Coc By 1.5-hour Bamboo Boat. You Will Be Surprised By The Charming Beauty Here With Paddy Fields, River, Water, Cloud, Sky, And A Stunning Cave System During The Boat Trip. All Make A Masterpiece That The Vietnamese People Called Ha Long Bay On Land Continue The Tour For 45 Mins - Cycling Around The Village To Discover The Life Of The Local People. ♦ Get On Car To Return To Hanoi ♦ Get Dropped Off At Hotel In Hanoi ♦ Overnight In Hanoi
A9: Hanoi Airport - 100 KM 2 hours - Ninh Binh Tour (With Lunch) - Tam Coc - Hotel Drop | B9: ● FULL DAY – NINH BINH TOUR ♦ (100 KM 2 hours Drive) ♦ Arrive In Noi Bai International Airport. ♦ Get Picked Up By Our Friendly Driver Then Depart For Ninh Binh Province Have A Short Break For 15 _ 20 Minutes To Relax ♦ Visit Hoa Lu, Ancient Capital Of Vietnam Between 968 And 1010. You Have A Chance To Learn About Vietnamese History In The Feudal System Under Dinh, Le, And Ly Dynasty ♦ Have A Buffet Lunch In The Restaurant With A Lot Of Local Foods Such As Goat Meat, Fish, Chicken, And Fried Rice &Vegetarian Foods Are Always Available In The Buffet Lunch ♦ Visit Tam Coc By 1.5-hour Bamboo Boat. You Will Be Surprised By The Charming Beauty Here With Paddy Fields, River, Water, Cloud, Sky, And A Stunning Cave System During The Boat Trip. All Make A Masterpiece That The Vietnamese People Called Ha Long Bay On Land ♦ Continue The Tour For 45 Mins - Cycling Around The Village To Discover The Life Of The Local People. ♦ Get On Car To Return To Hanoi ♦ Get Dropped Off At Hotel In Hanoi ♦ Overnight In Hanoi
A10: Hanoi Hotel - 100 KM 2 hours - Ninh Binh Tour - Tam Coc - Hotel Drop | B10: ● FULL DAY – NINH BINH TOUR ♦ (100 KM 2 hours Drive) ♦ Get Picked Up By Our Friendly Driver Then Depart For Ninh Binh Province Have A Short Break For 15 _ 20 Minutes To Relax ♦ Visit Hoa Lu, Ancient Capital Of Vietnam Between 968 And 1010. You Have A Chance To Learn About Vietnamese History In The Feudal System Under Dinh, Le, And Ly Dynasty ♦ Visit Tam Coc By 1.5-hour Bamboo Boat. You Will Be Surprised By The Charming Beauty Here With Paddy Fields, River, Water, Cloud, Sky, And A Stunning Cave System During The Boat Trip. All Make A Masterpiece That The Vietnamese People Called Ha Long Bay On Land Continue The Tour For 45 Mins - Cycling Around The Village To Discover The Life Of The Local People. ♦ Get On Car To Return To Hanoi ♦ Get Dropped Off At Hotel In Hanoi ♦ Overnight In Hanoi
A11: Hanoi Hotel - 100 KM 2 hours - Ninh Binh Tour (With Lunch ) - Tam Coc - Hotel Drop | B11: ● FULL DAY – NINH BINH TOUR ♦ (100 KM 2 hours Drive) ♦ Get Picked Up By Our Friendly Driver Then Depart For Ninh Binh Province Have A Short Break For 15 _ 20 Minutes To Relax ♦ Visit Hoa Lu, Ancient Capital Of Vietnam Between 968 And 1010. You Have A Chance To Learn About Vietnamese History In The Feudal System Under Dinh, Le, And Ly Dynasty ♦ Have A Buffet Lunch In The Restaurant With A Lot Of Local Foods Such As Goat Meat, Fish, Chicken, And Fried Rice &Vegetarian Foods Are Always Available In The Buffet Lunch ♦ Visit Tam Coc By 1.5-hour Bamboo Boat. You Will Be Surprised By The Charming Beauty Here With Paddy Fields, River, Water, Cloud, Sky, And A Stunning Cave System During The Boat Trip. All Make A Masterpiece That The Vietnamese People Called Ha Long Bay On Land ♦ Continue The Tour For 45 Mins - Cycling Around The Village To Discover The Life Of The Local People. ♦ Get On Car To Return To Hanoi ♦ Get Dropped Off At Hotel In Hanoi ♦ Overnight In Hanoi
A12: Hanoi Airport - 200 Km 4 hours drive - Halong bay- 11:30 AM need to reach at Halong bay for cruise depart | B12: ● HANOI ARRIVAL - CRUISE WITH TI TOP & CAVE ROUTE– OVERNIGHT ON CRUISE ♦ Arrive Hanoi Airport Transfer To Ha Long Bay. Spending 3.5 Hours On Car To See How Beautiful Landscape Of Red River Delta. Upon Arrival At The Harbor, Meet Our Cruise Crew To Join The Fantastic Journey Around The New Seven Wonder On Luxury Cruise. Welcome And Check-in To Cruise, Your Lunch Will Be Served While The Boat Slowly Slides On Romantic Waves Of The Sea. Afternoon Is Time For Many Interesting Activities Such As: Visiting The Cave, Kayaking, Swimming, Sunbathing, Cooking Class. Enjoy Special Dinner Dish And Continuing Night Program With The Crew. ♦ Lunch And Dinner On Board. ♦ Overnight On Boat In Ha Long Bay. ♦ Please Note: The Program May Be Little Varied Upon The Cruise You Choose.
... A81: Phu Quoc Hotel - Phu Quoc Airport Drop | B81: ● PHU QUOC DEPARTURE ♦ Breakfast In Hotel ♦ Our Private Car Will Pick You Up From The Hotel And Drop You At Phu Quoc Airport.

Sheet Table 3
A1: Meeting Point
A3: AIRPORT | B3: INTERNATIONAL ARRIVAL | C3: DOMESTIC ARRIVAL
A4: HO CHI MINH | B4: ARRIVAL PILLAR - 10 GF | C4: ARRIVAL HALL- A1
A5: HANOI | B5: T2 - GATE A & GATE B | C5: T1 - GATE A,B,E
A6: DANANG | B6: GATE 5 | C6: GATE 5
A7: PHU QUOC | B7: Exit Gate | C7: Exit Gate
A9: Terms & Conditions | Advisory Notes
A10: Arrival Notes:
A11: ➢ On the starting day of Tour, Once client local vietnameese number received then WhatsApp group will be created by us, kindly use that for any further communication.
A12: ➢ Guest need to proceed to the Arrival Or Exit Gate & look for airport representative with guest name on Pla card.
A13: ➢ Customer need to wait for 10-15 minutes at the arrival gate once they meet our Airport Representative, Because car park at parking point.
A14: ➢ The maximum waiting period is 90 mins from time of flight landing.
A15: ➢ All Tours and Transfer max waiting period is 10 min SIC basis and 30 Min on PVT Basis.
A16: ➢ Guest need to take care of their belongings while leaving Hotel or Car, We will not be responsible for any belongings.
A18: Hotel Notes:
A19: ➢ Standard Check in Time: 02:00 Pm *Early check in is subject to hotel availability & hotel may charge directly to the guest.
A20: ➢ Standard Check out Time: 11:00 Am Late checkout subject to hotel availability & hotel may charge directly to the guest.
A21: ➢ Hotel may ask for SECURITY DEPOSIT up to 200 USD Or Passport depends on the hotels policy.
... A27: ➢ For Visit to Island, all guest are advised to carry extra pair of clothes, towel and slippers.

Sheet Table 3 (2)
A1: Travel Itinerary
B3: Meeting Point At Airport Arrival
B5: AIRPROT | C5: INTERNATIONAL ARRIVAL | D5: DOMESTIC ARRIVAL
B6: HO CHI MINH | C6: ARRIVAL - T2 - PILLAR 10 GF | D6: T1 - ARRIVAL - A1
B7: HANOI | C7: ARRIVAL - T2 - PILLAR 10 1F | D7: T1 - ARRIVAL - E2
B8: DANANG | C8: EXIT GATE PARKING | D8: T1 ARRIVAL PILLAR 4,5
B9: PHU QUOC | C9: EXIT GATE PARKING | D9: EXIT GATE PARKING
A11: Terms & Conditions | Advisory Notes
A12: Arrival Notes:
A13: ➢ On the starting day of Tour, Once client local vietnameese number received then WhatsApp group will be created by us, kindly use that for any further communication.
A14: ➢ Guest need to proceed to the Arrival Or Exit Gate & look for airport representative with guest name on Pla card.
A15: ➢ Customer need to wait for 10-15 minutes at the arrival gate once they meet our Airport Representative, Because car park at parking point.
A16: ➢ The maximum waiting period is 90 mins from time of flight landing.
A17: ➢ All Tours and Transfer max waiting period is 10 min SIC basis and 30 Min on PVT Basis.
A18: ➢ Guest need to take care of their belongings while leaving Hotel or Car, We will not be responsible for any belongings.
A20: Hotel Notes:
A21: ➢ Standard Check in Time: 02:00 Pm *Early check in is subject to hotel availability & hotel may charge directly to the guest.
A22: ➢ Standard Check out Time: 11:00 Am Late checkout subject to hotel availability & hotel may charge directly to the guest.
A23: ➢ Hotel may ask for SECURITY DEPOSIT up to 200 USD Or Passport depends on the hotels policy.
... A38: ➢ For any amendment requests in the Itinerary, the request shall be subject to possibilities.
